<?xml version="1.0" ?>
<!-- =================================================================================== -->
<!-- |    This document was autogenerated by xacro from myddbot.xacro                  | -->
<!-- |    EDITING THIS FILE BY HAND IS NOT RECOMMENDED                                 | -->
<!-- =================================================================================== -->
<robot name="myddbot">
  <!--
        |      caster     |    ^
        |                 |    | length
        |        ^ x      |    |
        |        |        |    |
      wl|<-   y<-O      ->|wr  v
         <-   baseline  ->
  -->
  <material name="red">
    <color rgba="0.8 0.0 0.0 1.0"/>
  </material>
  <material name="green">
    <color rgba="0.0 0.8 0.0 1.0"/>
  </material>
  <material name="blue">
    <color rgba="0.0 0.0 0.8 1.0"/>
  </material>
  <material name="grey">
    <color rgba="0.6 0.6 0.6 1"/>
  </material>
  <material name="black">
    <color rgba="0.1 0.1 0.1 1"/>
  </material>
  <!-- see: https://www.ros.org/reps/rep-0120.html -->
  <link name="base_footprint"/>
  <link name="base_link">
    <visual name="base_link_visual">
      <geometry>
        <box size="1.3 0.95 0.1"/>
      </geometry>
      <origin rpy="0 0 0" xyz="0.65 0 0"/>
      <material name="grey"/>
    </visual>
    <collision>
      <geometry>
        <box size="1.3 0.95 0.1"/>
      </geometry>
      <origin rpy="0 0 0" xyz="0.65 0 0"/>
    </collision>
    <inertial>
      <mass value="2.0"/>
      <inertia ixx="0.16833333333333333" ixy="0.0" ixz="0.0" iyy="0.2833333333333333" iyz="0.0" izz="0.44833333333333336"/>
      <origin rpy="0 0 0" xyz="0.65 0 0"/>
    </inertial>
  </link>
  <joint name="base_footprint_base_link_joint" type="fixed">
    <origin rpy="0 0 0" xyz="0 0 0.3"/>
    <axis xyz="0 0 1"/>
    <parent link="base_footprint"/>
    <child link="base_link"/>
  </joint>
  <link name="wheel_left">
    <visual>
      <origin rpy="0 0 0" xyz="0 0 0"/>
      <geometry>
        <cylinder length="0.05" radius="0.3"/>
      </geometry>
      <material name="blue"/>
    </visual>
    <inertial>
      <origin rpy="0 0 0" xyz="0 0 0"/>
      <mass value="0.5"/>
      <inertia ixx="0.0225" ixy="0.0" ixz="0.0" iyy="0.011354166666666667" iyz="0.0" izz="0.011354166666666667"/>
    </inertial>
    <collision>
      <origin rpy="0 0 0" xyz="0 0 0"/>
      <geometry>
        <cylinder length="0.05" radius="0.3"/>
      </geometry>
    </collision>
  </link>
  <joint name="base_link_wheel_left_joint" type="continuous">
    <parent link="base_link"/>
    <child link="wheel_left"/>
    <origin rpy="-1.5707963267948966 0 0" xyz="0.0 0.55 0"/>
    <axis rpy="0 0 0" xyz="0.0 0.0 1.0"/>
    <limit effort="100" velocity="100"/>
    <dynamics damping="0.0" friction="0.0"/>
  </joint>
  <link name="wheel_right">
    <visual>
      <origin rpy="0 0 0" xyz="0 0 0"/>
      <geometry>
        <cylinder length="0.05" radius="0.3"/>
      </geometry>
      <material name="blue"/>
    </visual>
    <inertial>
      <origin rpy="0 0 0" xyz="0 0 0"/>
      <mass value="0.5"/>
      <inertia ixx="0.0225" ixy="0.0" ixz="0.0" iyy="0.011354166666666667" iyz="0.0" izz="0.011354166666666667"/>
    </inertial>
    <collision>
      <origin rpy="0 0 0" xyz="0 0 0"/>
      <geometry>
        <cylinder length="0.05" radius="0.3"/>
      </geometry>
    </collision>
  </link>
  <joint name="base_link_wheel_right_joint" type="continuous">
    <parent link="base_link"/>
    <child link="wheel_right"/>
    <origin rpy="-1.5707963267948966 0 0" xyz="0.0 -0.55 0"/>
    <axis rpy="0 0 0" xyz="0.0 0.0 1.0"/>
    <limit effort="100" velocity="100"/>
    <dynamics damping="0.0" friction="0.0"/>
  </joint>
  <link name="caster_body">
    <visual>
      <geometry>
        <cylinder length="0.06" radius="0.06"/>
      </geometry>
      <material name="black"/>
    </visual>
    <!-- caster wheel goes through caster body so don't put collision object here -->
    <!-- collision>
      <geometry>
	<cylinder length="${caster_body_length}" radius="${caster_body_radius}" />
      </geometry>
    </collision -->
    <inertial>
      <origin rpy="0 0 0" xyz="0 0 0"/>
      <mass value="0.5"/>
      <inertia ixx="0.0009" ixy="0.0" ixz="0.0" iyy="0.0006" iyz="0.0" izz="0.0006"/>
    </inertial>
  </link>
  <joint name="base_link_caster_body_joint" type="continuous">
    <axis xyz="0 0 1"/>
    <origin rpy="0 0 0" xyz="1.1800000000000002 0 -0.08"/>
    <parent link="base_link"/>
    <child link="caster_body"/>
  </joint>
  <link name="caster_wheel">
    <visual>
      <geometry>
        <cylinder length="0.022000000000000006" radius="0.11000000000000001"/>
      </geometry>
      <material name="black"/>
    </visual>
    <collision>
      <geometry>
        <cylinder length="0.022000000000000006" radius="0.11000000000000001"/>
      </geometry>
    </collision>
    <inertial>
      <origin rpy="0 0 0" xyz="0 0 0"/>
      <mass value="0.5"/>
      <inertia ixx="0.0030250000000000008" ixy="0.0" ixz="0.0" iyy="0.0015326666666666672" iyz="0.0" izz="0.0015326666666666672"/>
    </inertial>
  </link>
  <joint name="caster_body_caster_wheel_joint" type="continuous">
    <axis xyz="0 0 1"/>
    <origin rpy="-1.5707963267948966 0 0" xyz="-0.041999999999999996 0 -0.11000000000000001"/>
    <parent link="caster_body"/>
    <child link="caster_wheel"/>
  </joint>
  <link name="camera1">
    <visual>
      <origin rpy="0 0 0" xyz="0 0 0"/>
      <geometry>
        <box size="0.1 0.1 0.1"/>
      </geometry>
      <material name="green"/>
    </visual>
    <inertial>
      <mass value="0.1"/>
      <origin rpy="0 0 0" xyz="0 0 0"/>
      <inertia ixx="0.0001666666666666667" ixy="0" ixz="0" iyy="0.0001666666666666667" iyz="0" izz="0.0001666666666666667"/>
    </inertial>
    <collision>
      <origin rpy="0 0 0" xyz="0 0 0"/>
      <geometry>
        <box size="0.1 0.1 0.1"/>
      </geometry>
    </collision>
  </link>
  <joint name="base_link_camera1_joint" type="fixed">
    <axis xyz="0 1 0"/>
    <origin rpy="0 0 0" xyz="1.25 0 0.1"/>
    <parent link="base_link"/>
    <child link="camera1"/>
  </joint>
  <!-- Hokuyo Laser Range Finder (LRF) -->
  <link name="lrf1">
    <visual>
      <origin rpy="0 0 0" xyz="0 0 0"/>
      <geometry>
        <mesh filename="package://myddbot/model/hokuyo.dae"/>
      </geometry>
    </visual>
    <inertial>
      <mass value="0.1"/>
      <origin rpy="0 0 0" xyz="0 0 0"/>
      <inertia ixx="0.0001666666666666667" ixy="0" ixz="0" iyy="0.0001666666666666667" iyz="0" izz="0.0001666666666666667"/>
    </inertial>
    <collision>
      <origin rpy="0 0 0" xyz="0 0 0"/>
      <geometry>
        <box size="0.1 0.1 0.1"/>
      </geometry>
    </collision>
  </link>
  <joint name="base_link_lrf1_joint" type="fixed">
    <axis xyz="0 1 0"/>
    <origin rpy="0 0 0" xyz="1.25 0 0.15000000000000002"/>
    <parent link="base_link"/>
    <child link="lrf1"/>
  </joint>
  <!-- IMU -->
  <!-- Gazebo plugins -->
  <!-- 
       Main source: http://gazebosim.org/tutorials?tut=ros_gzplugins&cat=connect_ros
       Source code: https://github.com/ros-simulation/gazebo_ros_pkgs/tree/kinetic-devel/gazebo_plugins/src
       Plugin types: http://gazebosim.org/tutorials?tut=plugins_hello_world&cat=write_plugin
       Tutorial: http://gazebosim.org/tutorials?tut=ros_gzplugins 
       Sensor Plugins: http://osrf-distributions.s3.amazonaws.com/gazebo/api/dev/classgazebo_1_1SensorPlugin.html 
      
  -->
  <gazebo reference="base_link">
    <material>Gazebo/Gray</material>
  </gazebo>
  <gazebo reference="caster_body">
    <material>Gazebo/Black</material>
  </gazebo>
  <gazebo reference="caster_wheel">
    <material>Gazebo/Black</material>
  </gazebo>
  <gazebo reference="wheel_left">
    <material>Gazebo/Blue</material>
  </gazebo>
  <gazebo reference="wheel_right">
    <material>Gazebo/Blue</material>
  </gazebo>
  <gazebo>
    <plugin filename="libgazebo_ros_diff_drive.so" name="differential_drive_controller">
      <legacyMode>false</legacyMode>
      <alwaysOn>true</alwaysOn>
      <updateRate>100</updateRate>
      <leftJoint>base_link_wheel_left_joint</leftJoint>
      <rightJoint>base_link_wheel_right_joint</rightJoint>
      <wheelSeparation>1.0</wheelSeparation>
      <wheelDiameter>0.6</wheelDiameter>
      <wheelTorque>20</wheelTorque>
      <commandTopic>cmd_vel</commandTopic>
      <odometryTopic>odom</odometryTopic>
      <odometryFrame>odom</odometryFrame>
      <robotBaseFrame>base_link</robotBaseFrame>
      <!-- Set to true to publish transforms for the wheel links, defaults to false -->
      <publishWheelTF>true</publishWheelTF>
      <!-- Set to true to publish transforms for the odometry, defaults to true -->
      <publishOdom>true</publishOdom>
      <!-- Set to true to publish sensor_msgs/JointState on /joint_states for the wheel joints, defaults to false -->
      <publishWheelJointState>true</publishWheelJointState>
    </plugin>
  </gazebo>
  <gazebo reference="camera1">
    <material>Gazebo/Green</material>
    <sensor name="camera1_sensor" type="camera">
      <update_rate>30.0</update_rate>
      <camera name="head">
        <horizontal_fov>1.3962634</horizontal_fov>
        <image>
          <width>800</width>
          <height>800</height>
          <format>R8G8B8</format>
        </image>
        <clip>
          <near>0.02</near>
          <far>300</far>
        </clip>
      </camera>
      <plugin filename="libgazebo_ros_camera.so" name="camera_controller">
        <alwaysOn>true</alwaysOn>
        <updateRate>0.0</updateRate>
        <cameraName>camera1</cameraName>
        <imageTopicName>image_raw</imageTopicName>
        <cameraInfoTopicName>camera_info</cameraInfoTopicName>
        <frameName>camera1</frameName>
        <hackBaseline>0.07</hackBaseline>
        <distortionK1>0.0</distortionK1>
        <distortionK2>0.0</distortionK2>
        <distortionK3>0.0</distortionK3>
        <distortionT1>0.0</distortionT1>
        <distortionT2>0.0</distortionT2>
      </plugin>
    </sensor>
  </gazebo>
  <!-- hokuyo -->
  <gazebo reference="lrf1">
    <sensor name="lrf1_sensor" type="ray">
      <pose>0 0 0 0 0 0</pose>
      <visualize>false</visualize>
      <update_rate>40</update_rate>
      <ray>
        <scan>
          <horizontal>
            <samples>720</samples>
            <resolution>1</resolution>
            <min_angle>-1.570796</min_angle>
            <max_angle>1.570796</max_angle>
          </horizontal>
        </scan>
        <range>
          <min>0.10</min>
          <max>30.0</max>
          <resolution>0.01</resolution>
        </range>
        <noise>
          <type>gaussian</type>
          <!-- Noise parameters based on published spec for Hokuyo laser
               achieving "+-30mm" accuracy at range < 10m.  A mean of 0.0m and
               stddev of 0.01m will put 99.7% of samples within 0.03m of the true
               reading. -->
          <mean>0.0</mean>
          <stddev>0.01</stddev>
        </noise>
      </ray>
      <plugin filename="libgazebo_ros_laser.so" name="gazebo_ros_head_hokuyo_controller">
        <topicName>/scan</topicName>
        <frameName>laser_link</frameName>
      </plugin>
    </sensor>
  </gazebo>
  <!--
 <gazebo reference="imu_link">
    <gravity>true</gravity>
    <sensor name="imu_sensor" type="imu">
      <always_on>true</always_on>
      <update_rate>100</update_rate>
      <visualize>true</visualize>
      <topic>__default_topic__</topic>
      <plugin filename="libgazebo_ros_imu_sensor.so" name="imu_plugin">
        <topicName>imu</topicName>
        <bodyName>imu_link</bodyName>
        <updateRateHZ>10.0</updateRateHZ>
        <gaussianNoise>0.0</gaussianNoise>
        <xyzOffset>0 0 0</xyzOffset>
        <rpyOffset>0 0 0</rpyOffset>
        <frameName>imu_link</frameName>
        <initialOrientationAsReference>false</initialOrientationAsReference>
      </plugin>
      <pose>0 0 0 0 0 0</pose>
    </sensor>
  </gazebo>

-->
  <!-- http://wiki.ros.org/urdf/Tutorials/Using%20a%20URDF%20in%20Gazebo -->
  <!-- 
  <gazebo>
    <plugin name="gazebo_ros_control" filename="libgazebo_ros_control.so">
      <robotNamespace>/</robotNamespace>
    </plugin>
  </gazebo>
  -->
</robot>

